(myenv) C:\Users\dell\Downloads\EnergyLanding (1)\EnergyLanding>python main.py
DEBUG:tzlocal:Looking up time zone info from registry
INFO:apscheduler.scheduler:Scheduler started
DEBUG:apscheduler.scheduler:Looking for jobs to run
DEBUG:apscheduler.scheduler:No jobs; waiting until a job is added
Traceback (most recent call last):
  File "C:\Users\dell\myenv\Lib\site-packages\sqlalchemy\engine\base.py", line 146, in __init__
    self._dbapi_connection = engine.raw_connection()
                             ~~~~~~~~~~~~~~~~~~~~~^^
  File "C:\Users\dell\myenv\Lib\site-packages\sqlalchemy\engine\base.py", line 3298, in raw_connection
    return self.pool.connect()
           ~~~~~~~~~~~~~~~~~^^
  File "C:\Users\dell\myenv\Lib\site-packages\sqlalchemy\pool\base.py", line 449, in connect
    return _ConnectionFairy._checkout(self)
           ~~~~~~~~~~~~~~~~~~~~~~~~~~^^^^^^
  File "C:\Users\dell\myenv\Lib\site-packages\sqlalchemy\pool\base.py", line 1263, in _checkout
    fairy = _ConnectionRecord.checkout(pool)
  File "C:\Users\dell\myenv\Lib\site-packages\sqlalchemy\pool\base.py", line 712, in checkout
    rec = pool._do_get()
  File "C:\Users\dell\myenv\Lib\site-packages\sqlalchemy\pool\impl.py", line 179, in _do_get
    with util.safe_reraise():
         ~~~~~~~~~~~~~~~~~^^
  File "C:\Users\dell\myenv\Lib\site-packages\sqlalchemy\util\langhelpers.py", line 146, in __exit__
    raise exc_value.with_traceback(exc_tb)
  File "C:\Users\dell\myenv\Lib\site-packages\sqlalchemy\pool\impl.py", line 177, in _do_get
    return self._create_connection()
           ~~~~~~~~~~~~~~~~~~~~~~~^^
  File "C:\Users\dell\myenv\Lib\site-packages\sqlalchemy\pool\base.py", line 390, in _create_connection
    return _ConnectionRecord(self)
  File "C:\Users\dell\myenv\Lib\site-packages\sqlalchemy\pool\base.py", line 674, in __init__
    self.__connect()
    ~~~~~~~~~~~~~~^^
  File "C:\Users\dell\myenv\Lib\site-packages\sqlalchemy\pool\base.py", line 900, in __connect
    with util.safe_reraise():
         ~~~~~~~~~~~~~~~~~^^
  File "C:\Users\dell\myenv\Lib\site-packages\sqlalchemy\util\langhelpers.py", line 146, in __exit__
    raise exc_value.with_traceback(exc_tb)
  File "C:\Users\dell\myenv\Lib\site-packages\sqlalchemy\pool\base.py", line 896, in __connect
    self.dbapi_connection = connection = pool._invoke_creator(self)
                                         ~~~~~~~~~~~~~~~~~~~~^^^^^^
  File "C:\Users\dell\myenv\Lib\site-packages\sqlalchemy\engine\create.py", line 646, in connect
    return dialect.connect(*cargs, **cparams)
           ~~~~~~~~~~~~~~~^^^^^^^^^^^^^^^^^^^
  File "C:\Users\dell\myenv\Lib\site-packages\sqlalchemy\engine\default.py", line 622, in connect
    return self.loaded_dbapi.connect(*cargs, **cparams)
           ~~~~~~~~~~~~~~~~~~~~~~~~~^^^^^^^^^^^^^^^^^^^
sqlite3.OperationalError: unable to open database file

The above exception was the direct cause of the following exception:

Traceback (most recent call last):
  File "C:\Users\dell\Downloads\EnergyLanding (1)\EnergyLanding\main.py", line 1, in <module>
    from app import app
  File "C:\Users\dell\Downloads\EnergyLanding (1)\EnergyLanding\app.py", line 96, in <module>
    db.create_all()
    ~~~~~~~~~~~~~^^
  File "C:\Users\dell\myenv\Lib\site-packages\flask_sqlalchemy\extension.py", line 900, in create_all
    self._call_for_binds(bind_key, "create_all")
    ~~~~~~~~~~~~~~~~~~~~^^^^^^^^^^^^^^^^^^^^^^^^
  File "C:\Users\dell\myenv\Lib\site-packages\flask_sqlalchemy\extension.py", line 881, in _call_for_binds
    getattr(metadata, op_name)(bind=engine)
    ~~~~~~~~~~~~~~~~~~~~~~~~~~^^^^^^^^^^^^^
  File "C:\Users\dell\myenv\Lib\site-packages\sqlalchemy\sql\schema.py", line 5907, in create_all
    bind._run_ddl_visitor(
    ~~~~~~~~~~~~~~~~~~~~~^
        ddl.SchemaGenerator, self, checkfirst=checkfirst, tables=tables
        ^^^^^^^^^^^^^^^^^^^^^^^^^^^^^^^^^^^^^^^^^^^^^^^^^^^^^^^^^^^^^^^
    )
    ^
  File "C:\Users\dell\myenv\Lib\site-packages\sqlalchemy\engine\base.py", line 3248, in _run_ddl_visitor
    with self.begin() as conn:
         ~~~~~~~~~~^^
  File "C:\Users\dell\AppData\Local\Programs\Python\Python313\Lib\contextlib.py", line 141, in __enter__
    return next(self.gen)
  File "C:\Users\dell\myenv\Lib\site-packages\sqlalchemy\engine\base.py", line 3238, in begin
    with self.connect() as conn:
         ~~~~~~~~~~~~^^
  File "C:\Users\dell\myenv\Lib\site-packages\sqlalchemy\engine\base.py", line 3274, in connect
    return self._connection_cls(self)
           ~~~~~~~~~~~~~~~~~~~~^^^^^^
  File "C:\Users\dell\myenv\Lib\site-packages\sqlalchemy\engine\base.py", line 148, in __init__
    Connection._handle_dbapi_exception_noconnection(
    ~~~~~~~~~~~~~~~~~~~~~~~~~~~~~~~~~~~~~~~~~~~~~~~^
        err, dialect, engine
        ^^^^^^^^^^^^^^^^^^^^
    )
    ^
  File "C:\Users\dell\myenv\Lib\site-packages\sqlalchemy\engine\base.py", line 2439, in _handle_dbapi_exception_noconnection
    raise sqlalchemy_exception.with_traceback(exc_info[2]) from e
  File "C:\Users\dell\myenv\Lib\site-packages\sqlalchemy\engine\base.py", line 146, in __init__
    self._dbapi_connection = engine.raw_connection()
                             ~~~~~~~~~~~~~~~~~~~~~^^
  File "C:\Users\dell\myenv\Lib\site-packages\sqlalchemy\engine\base.py", line 3298, in raw_connection
    return self.pool.connect()
           ~~~~~~~~~~~~~~~~~^^
  File "C:\Users\dell\myenv\Lib\site-packages\sqlalchemy\pool\base.py", line 449, in connect
    return _ConnectionFairy._checkout(self)
           ~~~~~~~~~~~~~~~~~~~~~~~~~~^^^^^^
  File "C:\Users\dell\myenv\Lib\site-packages\sqlalchemy\pool\base.py", line 1263, in _checkout
    fairy = _ConnectionRecord.checkout(pool)
  File "C:\Users\dell\myenv\Lib\site-packages\sqlalchemy\pool\base.py", line 712, in checkout
    rec = pool._do_get()
  File "C:\Users\dell\myenv\Lib\site-packages\sqlalchemy\pool\impl.py", line 179, in _do_get
    with util.safe_reraise():
         ~~~~~~~~~~~~~~~~~^^
  File "C:\Users\dell\myenv\Lib\site-packages\sqlalchemy\util\langhelpers.py", line 146, in __exit__
    raise exc_value.with_traceback(exc_tb)
  File "C:\Users\dell\myenv\Lib\site-packages\sqlalchemy\pool\impl.py", line 177, in _do_get
    return self._create_connection()
           ~~~~~~~~~~~~~~~~~~~~~~~^^
  File "C:\Users\dell\myenv\Lib\site-packages\sqlalchemy\pool\base.py", line 390, in _create_connection
    return _ConnectionRecord(self)
  File "C:\Users\dell\myenv\Lib\site-packages\sqlalchemy\pool\base.py", line 674, in __init__
    self.__connect()
    ~~~~~~~~~~~~~~^^
  File "C:\Users\dell\myenv\Lib\site-packages\sqlalchemy\pool\base.py", line 900, in __connect
    with util.safe_reraise():
         ~~~~~~~~~~~~~~~~~^^
  File "C:\Users\dell\myenv\Lib\site-packages\sqlalchemy\util\langhelpers.py", line 146, in __exit__
    raise exc_value.with_traceback(exc_tb)
  File "C:\Users\dell\myenv\Lib\site-packages\sqlalchemy\pool\base.py", line 896, in __connect
    self.dbapi_connection = connection = pool._invoke_creator(self)
                                         ~~~~~~~~~~~~~~~~~~~~^^^^^^
  File "C:\Users\dell\myenv\Lib\site-packages\sqlalchemy\engine\create.py", line 646, in connect
    return dialect.connect(*cargs, **cparams)
           ~~~~~~~~~~~~~~~^^^^^^^^^^^^^^^^^^^
  File "C:\Users\dell\myenv\Lib\site-packages\sqlalchemy\engine\default.py", line 622, in connect
    return self.loaded_dbapi.connect(*cargs, **cparams)
           ~~~~~~~~~~~~~~~~~~~~~~~~~^^^^^^^^^^^^^^^^^^^
sqlalchemy.exc.OperationalError: (sqlite3.OperationalError) unable to open database file
(Background on this error at: https://sqlalche.me/e/20/e3q8)